# 异常

## try catch fianlly

### 职责和定义
**try 块**：用于捕获异常。其后可接零个或多个catch块，如果没有catch块，则必须跟一个finally块。

**catch 块**：用于处理try捕获到的异常。

**finally 块**：无论是否捕获或处理异常，finally块里的语句都会被执行。当在try块或catch块中遇到return语句时，finally语句块将在方法返回之前被执行。在以下4种特殊情况下，finally块不会被执行：

```
1）在finally语句块中发生了异常。
2）在前面的代码中用了System.exit()退出程序。
3）程序所在的线程死亡。
4）关闭CPU。
```

### 执行顺序
1)当try没有捕获到异常时：try语句块中的语句逐一被执行，程序将跳过catch语句块，执行finally语句块和其后的语句；

2)当try语句块里的某条语句出现异常时，而没有处理此异常的catch语句块时，此异常将会抛给JVM处理，finally语句块里的语句还是会被执行，但finally语句块后的语句不会被执行；

3)在try语句块中是按照顺序来执行的，当执行到某一条语句出现异常时，程序将跳到catch语句块，并与catch语句块逐一匹配，找到与之对应的处理程序，其他的catch语句块将不会被执行，而try语句块中，出现异常之后的语句也不会被执行，catch语句块执行完后，执行finally语句块里的语句，最后执行finally语句块后的语句；


## 异常链的使用

定义三个异常类：ExceptionA,ExceptionB,ExceptionC

```java
public class ExceptionA extends Exception {
    public ExceptionA(String str) {
        super();
    }
}
 
public class ExceptionB extends ExceptionA {
 
    public ExceptionB(String str) {
        super(str);
    }
}
 
public class ExceptionC extends ExceptionA {
    public ExceptionC(String str) {
        super(str);
    }
}
```

异常丢失的情况

```java
public class NeverCaught {
    static void f() throws ExceptionB{
        throw new ExceptionB("exception b");
    }
 
    static void g() throws ExceptionC {
        try {
            f();
        } catch (ExceptionB e) {
            ExceptionC c = new ExceptionC("exception a");
            throw c;
        }
    }
 
    public static void main(String[] args) {
            try {
                g();
            } catch (ExceptionC e) {
                e.printStackTrace();
            }
    }
 
}
/*
exception.ExceptionC
at exception.NeverCaught.g(NeverCaught.java:12)
at exception.NeverCaught.main(NeverCaught.java:19)
*/

```

上面的情况相当于少了一种异常，这在我们排错的过程中非常的不利。那我们遇到上面的情况应该怎么办呢？这就是异常链的用武之地：保存异常信息，在抛出另外一个异常的同时不丢失原来的异常。

```java
public class NeverCaught {
    static void f() throws ExceptionB{
        throw new ExceptionB("exception b");
    }
 
    static void g() throws ExceptionC {
        try {
            f();
        } catch (ExceptionB e) {
            ExceptionC c = new ExceptionC("exception a");
            //异常连
            c.initCause(e);
            throw c;
        }
    }
 
    public static void main(String[] args) {
            try {
                g();
            } catch (ExceptionC e) {
                e.printStackTrace();
            }
    }
 
}
/*
exception.ExceptionC
at exception.NeverCaught.g(NeverCaught.java:12)
at exception.NeverCaught.main(NeverCaught.java:21)
Caused by: exception.ExceptionB
at exception.NeverCaught.f(NeverCaught.java:5)
at exception.NeverCaught.g(NeverCaught.java:10)
... 1 more
*/

```

## 异常的处理和建议

1.只在必要使用异常的地方才使用异常，不要用异常去控制程序的流程

2.切忌使用空catch块

3.检查异常和非检查异常的选择
`在一般情况下，我觉得尽量将检查异常转变为非检查异常交给上层处理`

4.注意catch块的顺序 `子类异常在前，父类在后`

5.不要将提供给用户看的信息放在异常信息里

6.避免多次在日志信息中记录同一个异常

7.异常处理尽量放在高层进行

8.在finally中释放资源


## 常见的异常

1.runtimeException子类

```
    1、 java.lang.ArrayIndexOutOfBoundsException
    数组索引越界异常。当对数组的索引值为负数或大于等于数组大小时抛出。
    2、java.lang.ArithmeticException
    算术条件异常。譬如：整数除零等。
    3、java.lang.NullPointerException
    空指针异常。当应用试图在要求使用对象的地方使用了null时，抛出该异常。譬如：调用null对象的实例方法、访问null对象的属性、计算null对象的长度、使用throw语句抛出null等等
    4、java.lang.ClassNotFoundException
    找不到类异常。当应用试图根据字符串形式的类名构造类，而在遍历CLASSPAH之后找不到对应名称的class文件时，抛出该异常。
   5、java.lang.NegativeArraySizeException  数组长度为负异常

   6、java.lang.ArrayStoreException 数组中包含不兼容的值抛出的异常

   7、java.lang.SecurityException 安全性异常

   8、java.lang.IllegalArgumentException 非法参数异常
```

2.IOException

```
IOException：操作输入流和输出流时可能出现的异常。

EOFException   文件已结束异常

FileNotFoundException   文件未找到异常
```

3.其他

```
ClassCastException    类型转换异常类

ArrayStoreException  数组中包含不兼容的值抛出的异常

SQLException   操作数据库异常类

NoSuchFieldException   字段未找到异常

NoSuchMethodException   方法未找到抛出的异常

NumberFormatException    字符串转换为数字抛出的异常

StringIndexOutOfBoundsException 字符串索引超出范围抛出的异常

IllegalAccessException  不允许访问某类异常

InstantiationException  当应用程序试图使用Class类中的newInstance()方法创建一个类的实例，而指定的类对象无法被实例化时，抛出该异常
```

**【参考】**
https://juejin.im/post/5ae66791f265da0b92655c5d

https://blog.csdn.net/hguisu/article/details/6155636